<mujoco model="mass_model">
   <compiler inertiafromgeom = "auto"
                       angle = "radian" />

   <option timestep   = "0.001"
           iterations = "50"
           integrator = "Euler"
           collision  = "all"
           gravity    = "0 0 0" />
   <asset>
     <texture  type    = "skybox"
               builtin = "flat"
               rgb1    = "1 1 1"
               rgb2    = "1 1 1"
               width   = "100"
               height  = "100" />

     <material name="mass_color"
               rgba="1 1 1 1"/>
   </asset>

   <worldbody>
     <body name="camera" pos="0 0 0">
        <camera name="myCamera" pos="0.7975 -3.19 -0.4785" euler="1.5707 0 0" />
      </body>

      <body name="mass" pos="0 0 0" euler="0 0 0">
          <joint name="slider_joint" ref="0" type="slide" axis="1 0 0" />
          <geom  name="mass_box" type="box" pos="0 0 0" material="mass_color" size="0.1 0.1 0.1" mass="1" />
      </body>

   </worldbody>

   <actuator>
      <motor joint="slider_joint" name = "mass_force_actuator" forcelimited="false" />
   </actuator>
</mujoco>
